[INFO/EvalSub-5] process shutting down
Process EvalSub-5:
Traceback (most recent call last):
  File "/home/rdchujf/anaconda3/envs/p37/lib/python3.7/multiprocessing/process.py", line 297, in _bootstrap
    self.run()
  File "/home/rdchujf/remote_sw/Agent_Eval.py", line 154, in run
    self.data.eval_reset_data()
  File "/home/rdchujf/remote_sw/Agent_Comm.py", line 81, in eval_reset_data
    assert len(self.l_r[idx]) == 0
AssertionError
[INFO/EvalSub-5] process exiting with exitcode 1
[INFO/EvalSub-4] process shutting down
[INFO/EvalSub-6] process shutting down
Process EvalSub-4:
Traceback (most recent call last):
  File "/home/rdchujf/anaconda3/envs/p37/lib/python3.7/multiprocessing/process.py", line 297, in _bootstrap
    self.run()
  File "/home/rdchujf/remote_sw/Agent_Eval.py", line 154, in run
    self.data.eval_reset_data()
  File "/home/rdchujf/remote_sw/Agent_Comm.py", line 81, in eval_reset_data
    assert len(self.l_r[idx]) == 0
AssertionError
[INFO/EvalSub-4] process exiting with exitcode 1
Process EvalSub-6:
Traceback (most recent call last):
  File "/home/rdchujf/anaconda3/envs/p37/lib/python3.7/multiprocessing/process.py", line 297, in _bootstrap
    self.run()
  File "/home/rdchujf/remote_sw/Agent_Eval.py", line 154, in run
    self.data.eval_reset_data()
  File "/home/rdchujf/remote_sw/Agent_Comm.py", line 81, in eval_reset_data
    assert len(self.l_r[idx]) == 0


SZ002410,20180716,
SZ001979,20180720,
SZ002008,20180720,
SZ000333,20180720,
SH601360,20180102,to 20180214
SH603019,20171205,

['SZ000001', 'SZ000002', 'SZ000063', 'SZ000066', 'SZ000069', 'SZ000100',
'SZ000333', 'SZ000425', 'SZ000568', 'SZ000596', 'SZ000625', 'SZ000627',
'SZ000651', 'SZ000656', 'SZ000661', 'SZ000671', 'SZ000703', 'SZ000708',
'SZ000709', 'SZ000723', 'SZ000725', 'SZ000728', 'SZ000768', 'SZ000776',
'SZ000783', 'SZ000786', 'SZ000858', 'SZ000860', 'SZ000876', 'SZ000895', 'SZ000938']

